2024-02-13 00:24:54,394 INFO    MainThread:1992 [internal.py:wandb_internal():87] W&B internal server running at pid: 1992, started at: 2024-02-13 00:24:54.393654
2024-02-13 00:24:54,397 INFO    WriterThread:1992 [datastore.py:open_for_write():77] open: D:\jichuang\CNN\mydata\wandb\run-20240213_002447-3naa6f2b\run-3naa6f2b.wandb
2024-02-13 00:24:54,398 DEBUG   HandlerThread:1992 [handler.py:handle_request():130] handle_request: check_version
2024-02-13 00:24:54,404 DEBUG   SenderThread:1992 [sender.py:send():238] send: header
2024-02-13 00:24:54,405 DEBUG   SenderThread:1992 [sender.py:send_request():252] send_request: check_version
2024-02-13 00:24:54,447 DEBUG   SenderThread:1992 [sender.py:send():238] send: run
2024-02-13 00:24:56,073 WARNING MainThread:1992 [internal.py:wandb_internal():146] Internal process interrupt: 1
2024-02-13 00:24:56,108 INFO    SenderThread:1992 [dir_watcher.py:__init__():169] watching files in: D:\jichuang\CNN\mydata\wandb\run-20240213_002447-3naa6f2b\files
2024-02-13 00:24:56,108 INFO    SenderThread:1992 [sender.py:_start_run_threads():825] run started: 3naa6f2b with start time 1707755087
2024-02-13 00:24:58,378 WARNING MainThread:1992 [internal.py:wandb_internal():146] Internal process interrupt: 2
2024-02-13 00:24:58,379 ERROR   MainThread:1992 [internal.py:wandb_internal():149] Internal process interrupted.
2024-02-13 00:24:58,424 INFO    WriterThread:1992 [datastore.py:close():281] close: D:\jichuang\CNN\mydata\wandb\run-20240213_002447-3naa6f2b\run-3naa6f2b.wandb
2024-02-13 00:24:58,424 INFO    HandlerThread:1992 [handler.py:finish():731] shutting down handler
2024-02-13 00:24:59,146 INFO    SenderThread:1992 [sender.py:finish():1091] shutting down sender
2024-02-13 00:24:59,147 INFO    SenderThread:1992 [dir_watcher.py:finish():283] shutting down directory watcher
2024-02-13 00:25:00,149 INFO    SenderThread:1992 [dir_watcher.py:finish():313] scan: D:\jichuang\CNN\mydata\wandb\run-20240213_002447-3naa6f2b\files
2024-02-13 00:25:00,150 INFO    SenderThread:1992 [dir_watcher.py:finish():327] scan save: D:\jichuang\CNN\mydata\wandb\run-20240213_002447-3naa6f2b\files\config.yaml config.yaml
2024-02-13 00:25:00,151 INFO    SenderThread:1992 [file_pusher.py:finish():177] shutting down file pusher
2024-02-13 00:25:00,151 INFO    SenderThread:1992 [file_pusher.py:join():182] waiting for file pusher
2024-02-13 00:25:00,536 ERROR   Thread-14 :1992 [internal_api.py:upload_file():1574] upload_file exception https://storage.googleapis.com/wandb-production.appspot.com/zhang-long/YOLOv8/3naa6f2b/config.yaml?Expires=1707841500&GoogleAccessId=gorilla-files-url-signer-man%40wandb-production.iam.gserviceaccount.com&Signature=LbbWOjVMmX6psbBJjy%2B9c28DADlrQGX%2FIaaWRF4OjIQ5k08Am6LpARvGmGzB4JAmz%2BLMY4XH1DikzXoyJClYbOcBNmCKU6%2BhbmB6CUbEilslsWanynponcqD%2FjeqYO5Q5Ua4CXaJAekfOO6l3CbOsJApvC9Bl9HGHkzrJwYEnCX6rDpryxhjeQO8tmYopSNBFtWtiX0zKBDcf7UMlDmWwvC%2BUtZqYCVsteiGg5%2BpqBLMuE6MirX8R8kB86isWVREpHZACufPe4uHNctcP9iuCMu7wnRs7kActNSFJeYhJHuAd0dbnzkcNBvb1paQlOpwA6Lao22ydHZS4%2BVc41xhsg%3D%3D HTTPSConnectionPool(host='storage.googleapis.com', port=443): Max retries exceeded with url: /wandb-production.appspot.com/zhang-long/YOLOv8/3naa6f2b/config.yaml?Expires=1707841500&GoogleAccessId=gorilla-files-url-signer-man%40wandb-production.iam.gserviceaccount.com&Signature=LbbWOjVMmX6psbBJjy%2B9c28DADlrQGX%2FIaaWRF4OjIQ5k08Am6LpARvGmGzB4JAmz%2BLMY4XH1DikzXoyJClYbOcBNmCKU6%2BhbmB6CUbEilslsWanynponcqD%2FjeqYO5Q5Ua4CXaJAekfOO6l3CbOsJApvC9Bl9HGHkzrJwYEnCX6rDpryxhjeQO8tmYopSNBFtWtiX0zKBDcf7UMlDmWwvC%2BUtZqYCVsteiGg5%2BpqBLMuE6MirX8R8kB86isWVREpHZACufPe4uHNctcP9iuCMu7wnRs7kActNSFJeYhJHuAd0dbnzkcNBvb1paQlOpwA6Lao22ydHZS4%2BVc41xhsg%3D%3D (Caused by NameResolutionError("<urllib3.connection.HTTPSConnection object at 0x0000029C02782A00>: Failed to resolve 'storage.googleapis.com' ([Errno 11004] getaddrinfo failed)"))
2024-02-13 00:25:01,559 ERROR   Thread-14 :1992 [internal_api.py:upload_file():1574] upload_file exception https://storage.googleapis.com/wandb-production.appspot.com/zhang-long/YOLOv8/3naa6f2b/config.yaml?Expires=1707841500&GoogleAccessId=gorilla-files-url-signer-man%40wandb-production.iam.gserviceaccount.com&Signature=LbbWOjVMmX6psbBJjy%2B9c28DADlrQGX%2FIaaWRF4OjIQ5k08Am6LpARvGmGzB4JAmz%2BLMY4XH1DikzXoyJClYbOcBNmCKU6%2BhbmB6CUbEilslsWanynponcqD%2FjeqYO5Q5Ua4CXaJAekfOO6l3CbOsJApvC9Bl9HGHkzrJwYEnCX6rDpryxhjeQO8tmYopSNBFtWtiX0zKBDcf7UMlDmWwvC%2BUtZqYCVsteiGg5%2BpqBLMuE6MirX8R8kB86isWVREpHZACufPe4uHNctcP9iuCMu7wnRs7kActNSFJeYhJHuAd0dbnzkcNBvb1paQlOpwA6Lao22ydHZS4%2BVc41xhsg%3D%3D HTTPSConnectionPool(host='storage.googleapis.com', port=443): Max retries exceeded with url: /wandb-production.appspot.com/zhang-long/YOLOv8/3naa6f2b/config.yaml?Expires=1707841500&GoogleAccessId=gorilla-files-url-signer-man%40wandb-production.iam.gserviceaccount.com&Signature=LbbWOjVMmX6psbBJjy%2B9c28DADlrQGX%2FIaaWRF4OjIQ5k08Am6LpARvGmGzB4JAmz%2BLMY4XH1DikzXoyJClYbOcBNmCKU6%2BhbmB6CUbEilslsWanynponcqD%2FjeqYO5Q5Ua4CXaJAekfOO6l3CbOsJApvC9Bl9HGHkzrJwYEnCX6rDpryxhjeQO8tmYopSNBFtWtiX0zKBDcf7UMlDmWwvC%2BUtZqYCVsteiGg5%2BpqBLMuE6MirX8R8kB86isWVREpHZACufPe4uHNctcP9iuCMu7wnRs7kActNSFJeYhJHuAd0dbnzkcNBvb1paQlOpwA6Lao22ydHZS4%2BVc41xhsg%3D%3D (Caused by NameResolutionError("<urllib3.connection.HTTPSConnection object at 0x0000029C02782D60>: Failed to resolve 'storage.googleapis.com' ([Errno 11004] getaddrinfo failed)"))
2024-02-13 00:25:03,617 ERROR   Thread-14 :1992 [internal_api.py:upload_file():1574] upload_file exception https://storage.googleapis.com/wandb-production.appspot.com/zhang-long/YOLOv8/3naa6f2b/config.yaml?Expires=1707841500&GoogleAccessId=gorilla-files-url-signer-man%40wandb-production.iam.gserviceaccount.com&Signature=LbbWOjVMmX6psbBJjy%2B9c28DADlrQGX%2FIaaWRF4OjIQ5k08Am6LpARvGmGzB4JAmz%2BLMY4XH1DikzXoyJClYbOcBNmCKU6%2BhbmB6CUbEilslsWanynponcqD%2FjeqYO5Q5Ua4CXaJAekfOO6l3CbOsJApvC9Bl9HGHkzrJwYEnCX6rDpryxhjeQO8tmYopSNBFtWtiX0zKBDcf7UMlDmWwvC%2BUtZqYCVsteiGg5%2BpqBLMuE6MirX8R8kB86isWVREpHZACufPe4uHNctcP9iuCMu7wnRs7kActNSFJeYhJHuAd0dbnzkcNBvb1paQlOpwA6Lao22ydHZS4%2BVc41xhsg%3D%3D HTTPSConnectionPool(host='storage.googleapis.com', port=443): Max retries exceeded with url: /wandb-production.appspot.com/zhang-long/YOLOv8/3naa6f2b/config.yaml?Expires=1707841500&GoogleAccessId=gorilla-files-url-signer-man%40wandb-production.iam.gserviceaccount.com&Signature=LbbWOjVMmX6psbBJjy%2B9c28DADlrQGX%2FIaaWRF4OjIQ5k08Am6LpARvGmGzB4JAmz%2BLMY4XH1DikzXoyJClYbOcBNmCKU6%2BhbmB6CUbEilslsWanynponcqD%2FjeqYO5Q5Ua4CXaJAekfOO6l3CbOsJApvC9Bl9HGHkzrJwYEnCX6rDpryxhjeQO8tmYopSNBFtWtiX0zKBDcf7UMlDmWwvC%2BUtZqYCVsteiGg5%2BpqBLMuE6MirX8R8kB86isWVREpHZACufPe4uHNctcP9iuCMu7wnRs7kActNSFJeYhJHuAd0dbnzkcNBvb1paQlOpwA6Lao22ydHZS4%2BVc41xhsg%3D%3D (Caused by NameResolutionError("<urllib3.connection.HTTPSConnection object at 0x0000029C02782490>: Failed to resolve 'storage.googleapis.com' ([Errno 11004] getaddrinfo failed)"))
2024-02-13 00:25:03,618 ERROR   Thread-14 :1992 [retry.py:__call__():126] Retry attempt failed:
Traceback (most recent call last):
  File "D:\anaconda\lib\site-packages\urllib3\connection.py", line 203, in _new_conn
    sock = connection.create_connection(
  File "D:\anaconda\lib\site-packages\urllib3\util\connection.py", line 60, in create_connection
    for res in socket.getaddrinfo(host, port, family, socket.SOCK_STREAM):
  File "D:\anaconda\lib\socket.py", line 918, in getaddrinfo
    for res in _socket.getaddrinfo(host, port, family, type, proto, flags):
socket.gaierror: [Errno 11004] getaddrinfo failed

The above exception was the direct cause of the following exception:

Traceback (most recent call last):
  File "D:\anaconda\lib\site-packages\urllib3\connectionpool.py", line 790, in urlopen
    response = self._make_request(
  File "D:\anaconda\lib\site-packages\urllib3\connectionpool.py", line 491, in _make_request
    raise new_e
  File "D:\anaconda\lib\site-packages\urllib3\connectionpool.py", line 467, in _make_request
    self._validate_conn(conn)
  File "D:\anaconda\lib\site-packages\urllib3\connectionpool.py", line 1096, in _validate_conn
    conn.connect()
  File "D:\anaconda\lib\site-packages\urllib3\connection.py", line 611, in connect
    self.sock = sock = self._new_conn()
  File "D:\anaconda\lib\site-packages\urllib3\connection.py", line 210, in _new_conn
    raise NameResolutionError(self.host, self, e) from e
urllib3.exceptions.NameResolutionError: <urllib3.connection.HTTPSConnection object at 0x0000029C02782490>: Failed to resolve 'storage.googleapis.com' ([Errno 11004] getaddrinfo failed)

The above exception was the direct cause of the following exception:

Traceback (most recent call last):
  File "D:\anaconda\lib\site-packages\requests\adapters.py", line 486, in send
    resp = conn.urlopen(
  File "D:\anaconda\lib\site-packages\urllib3\connectionpool.py", line 844, in urlopen
    retries = retries.increment(
  File "D:\anaconda\lib\site-packages\urllib3\util\retry.py", line 515, in increment
    raise MaxRetryError(_pool, url, reason) from reason  # type: ignore[arg-type]
urllib3.exceptions.MaxRetryError: HTTPSConnectionPool(host='storage.googleapis.com', port=443): Max retries exceeded with url: /wandb-production.appspot.com/zhang-long/YOLOv8/3naa6f2b/config.yaml?Expires=1707841500&GoogleAccessId=gorilla-files-url-signer-man%40wandb-production.iam.gserviceaccount.com&Signature=LbbWOjVMmX6psbBJjy%2B9c28DADlrQGX%2FIaaWRF4OjIQ5k08Am6LpARvGmGzB4JAmz%2BLMY4XH1DikzXoyJClYbOcBNmCKU6%2BhbmB6CUbEilslsWanynponcqD%2FjeqYO5Q5Ua4CXaJAekfOO6l3CbOsJApvC9Bl9HGHkzrJwYEnCX6rDpryxhjeQO8tmYopSNBFtWtiX0zKBDcf7UMlDmWwvC%2BUtZqYCVsteiGg5%2BpqBLMuE6MirX8R8kB86isWVREpHZACufPe4uHNctcP9iuCMu7wnRs7kActNSFJeYhJHuAd0dbnzkcNBvb1paQlOpwA6Lao22ydHZS4%2BVc41xhsg%3D%3D (Caused by NameResolutionError("<urllib3.connection.HTTPSConnection object at 0x0000029C02782490>: Failed to resolve 'storage.googleapis.com' ([Errno 11004] getaddrinfo failed)"))

During handling of the above exception, another exception occurred:

Traceback (most recent call last):
  File "D:\anaconda\lib\site-packages\wandb\sdk\internal\internal_api.py", line 1571, in upload_file
    response = requests.put(url, data=progress, headers=extra_headers)
  File "D:\anaconda\lib\site-packages\requests\api.py", line 130, in put
    return request("put", url, data=data, **kwargs)
  File "D:\anaconda\lib\site-packages\requests\api.py", line 59, in request
    return session.request(method=method, url=url, **kwargs)
  File "D:\anaconda\lib\site-packages\requests\sessions.py", line 589, in request
    resp = self.send(prep, **send_kwargs)
  File "D:\anaconda\lib\site-packages\requests\sessions.py", line 703, in send
    r = adapter.send(request, **kwargs)
  File "D:\anaconda\lib\site-packages\requests\adapters.py", line 519, in send
    raise ConnectionError(e, request=request)
requests.exceptions.ConnectionError: HTTPSConnectionPool(host='storage.googleapis.com', port=443): Max retries exceeded with url: /wandb-production.appspot.com/zhang-long/YOLOv8/3naa6f2b/config.yaml?Expires=1707841500&GoogleAccessId=gorilla-files-url-signer-man%40wandb-production.iam.gserviceaccount.com&Signature=LbbWOjVMmX6psbBJjy%2B9c28DADlrQGX%2FIaaWRF4OjIQ5k08Am6LpARvGmGzB4JAmz%2BLMY4XH1DikzXoyJClYbOcBNmCKU6%2BhbmB6CUbEilslsWanynponcqD%2FjeqYO5Q5Ua4CXaJAekfOO6l3CbOsJApvC9Bl9HGHkzrJwYEnCX6rDpryxhjeQO8tmYopSNBFtWtiX0zKBDcf7UMlDmWwvC%2BUtZqYCVsteiGg5%2BpqBLMuE6MirX8R8kB86isWVREpHZACufPe4uHNctcP9iuCMu7wnRs7kActNSFJeYhJHuAd0dbnzkcNBvb1paQlOpwA6Lao22ydHZS4%2BVc41xhsg%3D%3D (Caused by NameResolutionError("<urllib3.connection.HTTPSConnection object at 0x0000029C02782490>: Failed to resolve 'storage.googleapis.com' ([Errno 11004] getaddrinfo failed)"))

During handling of the above exception, another exception occurred:

Traceback (most recent call last):
  File "D:\anaconda\lib\site-packages\wandb\sdk\lib\retry.py", line 102, in __call__
    result = self._call_fn(*args, **kwargs)
  File "D:\anaconda\lib\site-packages\wandb\sdk\internal\internal_api.py", line 1583, in upload_file
    six.reraise(type(e), e, sys.exc_info()[2])
  File "D:\anaconda\lib\site-packages\six.py", line 718, in reraise
    raise value.with_traceback(tb)
  File "D:\anaconda\lib\site-packages\wandb\sdk\internal\internal_api.py", line 1571, in upload_file
    response = requests.put(url, data=progress, headers=extra_headers)
  File "D:\anaconda\lib\site-packages\requests\api.py", line 130, in put
    return request("put", url, data=data, **kwargs)
  File "D:\anaconda\lib\site-packages\requests\api.py", line 59, in request
    return session.request(method=method, url=url, **kwargs)
  File "D:\anaconda\lib\site-packages\requests\sessions.py", line 589, in request
    resp = self.send(prep, **send_kwargs)
  File "D:\anaconda\lib\site-packages\requests\sessions.py", line 703, in send
    r = adapter.send(request, **kwargs)
  File "D:\anaconda\lib\site-packages\requests\adapters.py", line 519, in send
    raise ConnectionError(e, request=request)
wandb.sdk.lib.retry.TransientError: None
2024-02-13 00:25:08,631 ERROR   Thread-14 :1992 [internal_api.py:upload_file():1574] upload_file exception https://storage.googleapis.com/wandb-production.appspot.com/zhang-long/YOLOv8/3naa6f2b/config.yaml?Expires=1707841500&GoogleAccessId=gorilla-files-url-signer-man%40wandb-production.iam.gserviceaccount.com&Signature=LbbWOjVMmX6psbBJjy%2B9c28DADlrQGX%2FIaaWRF4OjIQ5k08Am6LpARvGmGzB4JAmz%2BLMY4XH1DikzXoyJClYbOcBNmCKU6%2BhbmB6CUbEilslsWanynponcqD%2FjeqYO5Q5Ua4CXaJAekfOO6l3CbOsJApvC9Bl9HGHkzrJwYEnCX6rDpryxhjeQO8tmYopSNBFtWtiX0zKBDcf7UMlDmWwvC%2BUtZqYCVsteiGg5%2BpqBLMuE6MirX8R8kB86isWVREpHZACufPe4uHNctcP9iuCMu7wnRs7kActNSFJeYhJHuAd0dbnzkcNBvb1paQlOpwA6Lao22ydHZS4%2BVc41xhsg%3D%3D HTTPSConnectionPool(host='storage.googleapis.com', port=443): Max retries exceeded with url: /wandb-production.appspot.com/zhang-long/YOLOv8/3naa6f2b/config.yaml?Expires=1707841500&GoogleAccessId=gorilla-files-url-signer-man%40wandb-production.iam.gserviceaccount.com&Signature=LbbWOjVMmX6psbBJjy%2B9c28DADlrQGX%2FIaaWRF4OjIQ5k08Am6LpARvGmGzB4JAmz%2BLMY4XH1DikzXoyJClYbOcBNmCKU6%2BhbmB6CUbEilslsWanynponcqD%2FjeqYO5Q5Ua4CXaJAekfOO6l3CbOsJApvC9Bl9HGHkzrJwYEnCX6rDpryxhjeQO8tmYopSNBFtWtiX0zKBDcf7UMlDmWwvC%2BUtZqYCVsteiGg5%2BpqBLMuE6MirX8R8kB86isWVREpHZACufPe4uHNctcP9iuCMu7wnRs7kActNSFJeYhJHuAd0dbnzkcNBvb1paQlOpwA6Lao22ydHZS4%2BVc41xhsg%3D%3D (Caused by NameResolutionError("<urllib3.connection.HTTPSConnection object at 0x0000029C026201C0>: Failed to resolve 'storage.googleapis.com' ([Errno 11004] getaddrinfo failed)"))
